<?xml version="1.0" ?>

<robot name="umouse" xmlns:xacro="http://ros.org/wiki/xacro">
  
  <!-- BGN - Include -->
  <xacro:include filename="$(find umouse_description)/urdf/links_joints.xacro" />
  <xacro:include filename="$(find umouse_description)/urdf/gazebo.xacro" />
  <!-- END - Include -->
  
  <material name="white">
    <color rgba="1 1 1 1"/>
  </material>

  <material name="black">
    <color rgba="0 0 0 1"/>
  </material>

  <material name="green">
    <color rgba="0.1 0.8 0.1 1"/>
  </material>

  <!-- BGN - Robot description -->

  <link name="base_link" />

  <joint name="base__base_link" type="fixed">
    <parent link="base_link"/>
    <child link="base"/>
  </joint>

  <!--m_link_mesh name="base"
              origin_rpy="1.5708 0.0 1.5708" origin_xyz="-0.04064 -0.02524 0.0"
              mass="0.2"
              ixx="0.5" ixy="0" ixz="0"
              iyy="1.0" iyz="0"
              izz="0.1"
              material="green"
              meshfile="package://umouse_description/meshes/umouse_base.stl"
              meshscale="0.001 0.001 0.001" /-->

  <link name="base">
    <origin rpy="0 0 0" xyz="0.00 0 0.00"/>
    <visual>
      <geometry>
        <box size="0.08 0.05 0.002"/>
      </geometry>
    </visual>
    <collision>
      <geometry>
        <box size="0.08 0.05 0.002"/>
      </geometry>
    </collision>
    <inertial>
      <mass value="0.5" />
      <inertia ixx="1.0" ixy="0.0" ixz="0.0" iyy="1.0" iyz="0.0" izz="1.0" />
    </inertial>

  </link>

  <link name="fcastor_wheel">
    <origin rpy="0 0 0" xyz="0.00 0 0.00"/>
    <visual>
      <geometry>
        <cylinder length="0.006" radius="0.0035"/>
      </geometry>
    </visual>
    <collision>
      <geometry>
        <cylinder length="0.006" radius="0.0035"/>
      </geometry>
    </collision>
    <inertial>
      <mass value="0.05" />
      <inertia ixx="0.001" ixy="0.0" ixz="0.0" iyy="0.001" iyz="0.0" izz="0.001" />
    </inertial>
  </link>
  
  <joint name="base__fcastor_wheel" type="continuous">
    <parent link="base"/>
    <child link="fcastor_wheel"/>
    <origin xyz="0.028 0 -0.005" rpy="1.5708 0 0"/>
    <axis xyz="0 0 1"/>
  </joint>

  <link name="bcastor_wheel">
    <origin rpy="0 0 0" xyz="0.00 0 0.00"/>
    <visual>
      <geometry>
        <cylinder length="0.006" radius="0.0035"/>
      </geometry>
    </visual>
    <collision>
      <geometry>
        <cylinder length="0.006" radius="0.0035"/>
      </geometry>
    </collision>
    <inertial>
      <mass value="0.05" />
      <inertia ixx="0.001" ixy="0.0" ixz="0.0" iyy="0.001" iyz="0.0" izz="0.001" />
    </inertial>
  </link>
  
  <joint name="base__bcastor_wheel" type="continuous">
    <parent link="base"/>
    <child link="bcastor_wheel"/>
    <origin xyz="-0.028 0 -0.005" rpy="1.5708 0 0"/>
    <axis xyz="0 0 1"/>
  </joint>

  <link name="left_wheel">
    <origin rpy="0 0 0" xyz="0.00 0 0.00"/>
    <visual>
      <geometry>
        <cylinder length="0.006" radius="0.016"/>
      </geometry>
    </visual>
    <collision>
      <geometry>
        <cylinder length="0.006" radius="0.016"/>
      </geometry>
    </collision>
    <inertial>
      <mass value="0.05" />
      <inertia ixx="0.001" ixy="0.0" ixz="0.0" iyy="0.001" iyz="0.0" izz="0.001" />
    </inertial>
  </link>
  
  <joint name="wheel_left_joint" type="continuous">
    <parent link="base"/>
    <child link="left_wheel"/>
    <origin xyz="0 0.032 0.007" rpy="1.5708 0 0"/>
    <axis xyz="0 0 -1"/>
  </joint>

  <link name="right_wheel">
    <origin rpy="0 0 0" xyz="0.00 0 0.00"/>
    <visual>
      <geometry>
        <cylinder length="0.009" radius="0.016"/>
      </geometry>
    </visual>
    <collision>
      <geometry>
        <cylinder length="0.009" radius="0.016"/>
      </geometry>
    </collision>
    <inertial>
      <mass value="0.05" />
      <inertia ixx="0.001" ixy="0.0" ixz="0.0" iyy="0.001" iyz="0.0" izz="0.001" />
    </inertial>
  </link>
  
  <joint name="wheel_right_joint" type="continuous">
    <parent link="base"/>
    <child link="right_wheel"/>
    <origin xyz="0 -0.032 0.007" rpy="1.5708 0 0"/>
    <axis xyz="0 0 -1"/>
  </joint>


  <!--m_link_mesh name="left_wheel"
              origin_rpy="1.5708 0 3.1416" origin_xyz="0 0 0"
              mass="0.1"
              ixx="1.0" ixy="0" ixz="0"
              iyy="1.0" iyz="0"
              izz="1.0"
              material="black"
              meshfile="package://umouse_description/meshes/umouse_wheel.stl"
              meshscale="0.001 0.001 0.001" />

  <joint name="wheel_left_joint" type="continuous">
      <parent link="base_link"/>
      <child link="left_wheel"/>
      <origin xyz="0.0 0.032 0.0071" rpy="0.0 0.0 0"/>
      <axis xyz="0 1 0"/>
  </joint>

  <m_link_mesh name="right_wheel"
              origin_rpy="1.5708 0 0.0" origin_xyz="0 0 0"
              mass="0.1"
              ixx="1.0" ixy="0" ixz="0"
              iyy="1.0" iyz="0"
              izz="1.0"
              material="black"
              meshfile="package://umouse_description/meshes/umouse_wheel.stl"
              meshscale="0.001 0.001 0.001" />

  <joint name="wheel_right_joint" type="continuous">
      <parent link="base_link"/>
      <child link="right_wheel"/>
      <origin xyz="0.0 -0.032 0.0071" rpy="0.0 0.0 0"/>
      <axis xyz="0 1 0"/>
  </joint-->

</robot>
